WARNING:tensorflow:From C:\Users\yangx\Documents\WPSDrive\347326463\WPS‘∆≈Ã\08_AI—ßœ∞\feng_shui\DeepFloorplan\DeepFloorplan\Lib\site-packages\tensorflow\python\compat\v2_compat.py:107: disable_resource_variables (from tensorflow.python.ops.variable_scope) is deprecated and will be removed in a future version.
Instructions for updating:
non-resource variables are not supported in the long term
Traceback (most recent call last):
  File "C:\Users\yangx\Documents\WPSDrive\347326463\WPS‘∆≈Ã\08_AI—ßœ∞\feng_shui\DeepFloorplan\DeepFloorplan\Lib\site-packages\tensorflow\python\client\session.py", line 1379, in _do_call
    return fn(*args)
           ^^^^^^^^^
  File "C:\Users\yangx\Documents\WPSDrive\347326463\WPS‘∆≈Ã\08_AI—ßœ∞\feng_shui\DeepFloorplan\DeepFloorplan\Lib\site-packages\tensorflow\python\client\session.py", line 1361, in _run_fn
    self._extend_graph()
  File "C:\Users\yangx\Documents\WPSDrive\347326463\WPS‘∆≈Ã\08_AI—ßœ∞\feng_shui\DeepFloorplan\DeepFloorplan\Lib\site-packages\tensorflow\python\client\session.py", line 1402, in _extend_graph
    tf_session.ExtendSession(self._session)
tensorflow.python.framework.errors_impl.InvalidArgumentError: Cannot assign a device for operation FNet/conv1_1/W/Initializer/random_uniform/RandomUniform: {{node FNet/conv1_1/W/Initializer/random_uniform/RandomUniform}} was explicitly assigned to /device:GPU:0 but available devices are [ /job:localhost/replica:0/task:0/device:CPU:0 ]. Make sure the device specification refers to a valid device. The requested device appears to be a GPU, but CUDA is not enabled.
	 [[FNet/conv1_1/W/Initializer/random_uniform/RandomUniform]]

During handling of the above exception, another exception occurred:

Traceback (most recent call last):
  File "C:\Users\yangx\Documents\WPSDrive\347326463\WPS‘∆≈Ã\08_AI—ßœ∞\feng_shui\DeepFloorplan\DeepFloorplan\Lib\site-packages\tensorflow\python\training\saver.py", line 1418, in restore
    sess.run(self.saver_def.restore_op_name,
  File "C:\Users\yangx\Documents\WPSDrive\347326463\WPS‘∆≈Ã\08_AI—ßœ∞\feng_shui\DeepFloorplan\DeepFloorplan\Lib\site-packages\tensorflow\python\client\session.py", line 969, in run
    result = self._run(None, fetches, feed_dict, options_ptr,
             ^^^^^^^^^^^^^^^^^^^^^^^^^^^^^^^^^^^^^^^^^^^^^^^^
  File "C:\Users\yangx\Documents\WPSDrive\347326463\WPS‘∆≈Ã\08_AI—ßœ∞\feng_shui\DeepFloorplan\DeepFloorplan\Lib\site-packages\tensorflow\python\client\session.py", line 1192, in _run
    results = self._do_run(handle, final_targets, final_fetches,
              ^^^^^^^^^^^^^^^^^^^^^^^^^^^^^^^^^^^^^^^^^^^^^^^^^^
  File "C:\Users\yangx\Documents\WPSDrive\347326463\WPS‘∆≈Ã\08_AI—ßœ∞\feng_shui\DeepFloorplan\DeepFloorplan\Lib\site-packages\tensorflow\python\client\session.py", line 1372, in _do_run
    return self._do_call(_run_fn, feeds, fetches, targets, options,
           ^^^^^^^^^^^^^^^^^^^^^^^^^^^^^^^^^^^^^^^^^^^^^^^^^^^^^^^^
  File "C:\Users\yangx\Documents\WPSDrive\347326463\WPS‘∆≈Ã\08_AI—ßœ∞\feng_shui\DeepFloorplan\DeepFloorplan\Lib\site-packages\tensorflow\python\client\session.py", line 1398, in _do_call
    raise type(e)(node_def, op, message)  # pylint: disable=no-value-for-parameter
    ^^^^^^^^^^^^^^^^^^^^^^^^^^^^^^^^^^^^
tensorflow.python.framework.errors_impl.InvalidArgumentError: Graph execution error:

Detected at node 'FNet/conv1_1/W/Initializer/random_uniform/RandomUniform' defined at (most recent call last):
Node: 'FNet/conv1_1/W/Initializer/random_uniform/RandomUniform'
Cannot assign a device for operation FNet/conv1_1/W/Initializer/random_uniform/RandomUniform: {{node FNet/conv1_1/W/Initializer/random_uniform/RandomUniform}} was explicitly assigned to /device:GPU:0 but available devices are [ /job:localhost/replica:0/task:0/device:CPU:0 ]. Make sure the device specification refers to a valid device. The requested device appears to be a GPU, but CUDA is not enabled.
	 [[FNet/conv1_1/W/Initializer/random_uniform/RandomUniform]]

During handling of the above exception, another exception occurred:

Traceback (most recent call last):
  File "C:\Users\yangx\Documents\WPSDrive\347326463\WPS‘∆≈Ã\08_AI—ßœ∞\feng_shui\DeepFloorplan\demo.py", line 127, in <module>
    main(FLAGS)
  File "C:\Users\yangx\Documents\WPSDrive\347326463\WPS‘∆≈Ã\08_AI—ßœ∞\feng_shui\DeepFloorplan\demo.py", line 97, in main
    saver.restore(sess, './pretrained/pretrained_r3d')
  File "C:\Users\yangx\Documents\WPSDrive\347326463\WPS‘∆≈Ã\08_AI—ßœ∞\feng_shui\DeepFloorplan\DeepFloorplan\Lib\site-packages\tensorflow\python\training\saver.py", line 1454, in restore
    raise _wrap_restore_error_with_msg(
tensorflow.python.framework.errors_impl.InvalidArgumentError: Restoring from checkpoint failed. This is most likely due to a mismatch between the current graph and the graph from the checkpoint. Please ensure that you have not altered the graph expected based on the checkpoint. Original error:

Graph execution error:

Detected at node 'FNet/conv1_1/W/Initializer/random_uniform/RandomUniform' defined at (most recent call last):
Node: 'FNet/conv1_1/W/Initializer/random_uniform/RandomUniform'
Cannot assign a device for operation FNet/conv1_1/W/Initializer/random_uniform/RandomUniform: {{node FNet/conv1_1/W/Initializer/random_uniform/RandomUniform}} was explicitly assigned to /device:GPU:0 but available devices are [ /job:localhost/replica:0/task:0/device:CPU:0 ]. Make sure the device specification refers to a valid device. The requested device appears to be a GPU, but CUDA is not enabled.
	 [[FNet/conv1_1/W/Initializer/random_uniform/RandomUniform]]
